<?xml version="1.0" encoding="UTF-8" ?>
<sdf version='1.4'>
  <world name='default'>
    <light name='sun' type='directional'>
      <cast_shadows>1</cast_shadows>
      <pose>0 0 10 0 -0 0</pose>
      <diffuse>0.8 0.8 0.8 1</diffuse>
      <specular>0.2 0.2 0.2 1</specular>
      <attenuation>
        <range>1000</range>
        <constant>0.9</constant>
        <linear>0.01</linear>
        <quadratic>0.001</quadratic>
      </attenuation>
      <direction>-0.5 0.1 -0.9</direction>
    </light>
    <model name='ground_plane'>
      <static>1</static>
      <link name='link'>
        <collision name='collision'>
          <geometry>
            <plane>
              <normal>0 0 1</normal>
              <size>100 100</size>
            </plane>
          </geometry>
          <surface>
            <friction>
              <ode>
                <mu>100</mu>
                <mu2>50</mu2>
              </ode>
            </friction>
            <bounce/>
            <contact>
              <ode/>
            </contact>
          </surface>
          <max_contacts>10</max_contacts>
        </collision>
        <visual name='visual'>
          <cast_shadows>0</cast_shadows>
          <geometry>
            <plane>
              <normal>0 0 1</normal>
              <size>100 100</size>
            </plane>
          </geometry>
          <material>
            <script>
              <uri>file://media/materials/scripts/gazebo.material</uri>
              <name>Gazebo/Grey</name>
            </script>
          </material>
        </visual>
        <velocity_decay>
          <linear>0</linear>
          <angular>0</angular>
        </velocity_decay>
        <self_collide>0</self_collide>
        <kinematic>0</kinematic>
        <gravity>1</gravity>
      </link>
    </model>
    <physics type='ode'>
      <max_step_size>0.001</max_step_size>
      <real_time_factor>1</real_time_factor>
      <real_time_update_rate>1000</real_time_update_rate>
      <gravity>0 0 -9.8</gravity>
    </physics>
    <scene>
      <ambient>0.4 0.4 0.4 1</ambient>
      <background>0.7 0.7 0.7 1</background>
      <shadows>1</shadows>
    </scene>
    <spherical_coordinates>
      <surface_model>EARTH_WGS84</surface_model>
      <latitude_deg>0</latitude_deg>
      <longitude_deg>0</longitude_deg>
      <elevation>0</elevation>
      <heading_deg>0</heading_deg>
    </spherical_coordinates>
    <state world_name='default'>
      <sim_time>224 232000000</sim_time>
      <real_time>27 884236464</real_time>
      <wall_time>1467198854 300936514</wall_time>
      <model name='ground_plane'>
        <pose>0 0 0 0 -0 0</pose>
        <link name='link'>
          <pose>0 0 0 0 -0 0</pose>
          <velocity>0 0 0 0 -0 0</velocity>
          <acceleration>0 0 0 0 -0 0</acceleration>
          <wrench>0 0 0 0 -0 0</wrench>
        </link>
      </model>
      <!--
      <model name='sjtu_drone'>
        <pose>2.99406 2.99458 3 -1.4e-05 -0.000112 0.090367</pose>
        <link name='base_link'>
          <pose>2.99406 2.99458 3 -1.4e-05 -0.000112 0.090367</pose>
          <velocity>-0.006092 0.000511 -0.010548 0.018503 -0.075538 0.010097</velocity>
          <acceleration>0 0 0 0 -0 0</acceleration>
          <wrench>0 0 0 0 -0 0</wrench>
        </link>
        <link name='camera_link'>
          <pose>3.09366 3.0036 2.96 -0.000269 -2.2e-05 0.033105</pose>
          <velocity>-0.00315 0.002251 -0.002851 -8.2e-05 -2e-06 0.003504</velocity>
          <acceleration>0 0 0 0 -0 0</acceleration>
          <wrench>0 0 0 0 -0 0</wrench>
        </link>
        <link name='gimbal_link'>
          <pose>3.09366 3.0036 2.96 -1.4e-05 -0.000112 0.090367</pose>
          <velocity>-0.003156 0.002254 -0.002853 0.01845 -0.075594 0.010069</velocity>
          <acceleration>0 0 0 0 -0 0</acceleration>
          <wrench>0 0 0 0 -0 0</wrench>
        </link>
        <link name='pitch_link'>
          <pose>3.09366 3.0036 2.96 -0.000269 -2.2e-05 0.033105</pose>
          <velocity>-0.003151 0.002251 -0.002852 -8.2e-05 -2e-06 0.003503</velocity>
          <acceleration>0 0 0 0 -0 0</acceleration>
          <wrench>0 0 0 0 -0 0</wrench>
        </link>
        <link name='roll_link'>
          <pose>3.09366 3.0036 2.96 -0.000269 -0.000113 0.033105</pose>
          <velocity>-0.003152 0.002252 -0.002852 0.002439 -0.076127 0.003524</velocity>
          <acceleration>0 0 0 0 -0 0</acceleration>
          <wrench>0 0 0 0 -0 0</wrench>
        </link>
        <link name='yaw_link'>
          <pose>3.09366 3.0036 2.96 -8e-06 -0.000113 0.033105</pose>
          <velocity>-0.003154 0.002253 -0.002852 0.018449 -0.075596 0.003524</velocity>
          <acceleration>0 0 0 0 -0 0</acceleration>
          <wrench>0 0 0 0 -0 0</wrench>
        </link>
      </model>
      -->
      </state>
    <model name='sjtu_drone'>
     <plugin name='simple_drone' filename='libplugin_drone.so'>
        <bodyName>base_link</bodyName>
        <imuTopic>/drone/imu</imuTopic>
        <rollpitchProportionalGain>10.0</rollpitchProportionalGain>
        <rollpitchDifferentialGain>5.0</rollpitchDifferentialGain>
        <rollpitchLimit>0.5</rollpitchLimit>
        <yawProportionalGain>2.0</yawProportionalGain>
        <yawDifferentialGain>1.0</yawDifferentialGain>
        <yawLimit>1.5</yawLimit>
        <velocityXYProportionalGain>5.0</velocityXYProportionalGain>
        <velocityXYDifferentialGain>2.3</velocityXYDifferentialGain>
        <velocityXYLimit>2</velocityXYLimit>
        <velocityZProportionalGain>5.0</velocityZProportionalGain>
        <velocityZDifferentialGain>1.0</velocityZDifferentialGain>
        <velocityZLimit>-1</velocityZLimit>
        <positionXYProportionalGain>1.1</positionXYProportionalGain>
        <positionXYDifferentialGain>0.0</positionXYDifferentialGain>
        <positionXYIntegralGain>0.0</positionXYIntegralGain>
        <positionXYLimit>5</positionXYLimit>
        <positionZProportionalGain>1.0</positionZProportionalGain>
        <positionZDifferentialGain>0.2</positionZDifferentialGain>
        <positionZLimit>-1</positionZLimit>
        <maxForce>30</maxForce>
        <motionSmallNoise>0.05</motionSmallNoise>
        <motionDriftNoise>0.03</motionDriftNoise>
        <motionDriftNoiseTime>5.0</motionDriftNoiseTime>
     </plugin>
     <pose>4 4 6.5 0 0 0</pose>
      <link name='base_link'>
        <pose>0 0 0 0 -0 0</pose>
        <inertial>
          <pose>0 0 0 0 -0 0</pose>
          <mass>1.477</mass>
          <inertia>
            <ixx>0.01152</ixx>
            <ixy>0</ixy>
            <ixz>0</ixz>
            <iyy>0.01152</iyy>
            <iyz>0</iyz>
            <izz>0.0218</izz>
          </inertia>
        </inertial>
        <collision name='base_link_collision'>
          <pose>0 0 0 0 -0 0</pose>
          <geometry>
          <box>
            <size>0.4 0.4 0.05</size>
          </box>
          </geometry>
          <max_contacts>10</max_contacts>
          <surface>
            <bounce/>
            <friction>
              <ode/>
            </friction>
            <contact>
              <ode/>
            </contact>
          </surface>
        </collision>
        <visual name='base_link_visual'>
          <pose>0 0 0 0 -0 0</pose>
          <geometry>
            <mesh>
              <scale>1 1 1</scale>
              <uri>model://hku_m100/quadrotor_4.dae</uri>
            </mesh>
          </geometry>
        </visual>
        <velocity_decay>
          <linear>0</linear>
          <angular>0</angular>
        </velocity_decay>
        <self_collide>0</self_collide>
        <kinematic>0</kinematic>
        <gravity>1</gravity>
      </link>
      <link name='camera_link'>
        <pose>0.0 0 -0.04 0 -0 0</pose>
        <inertial>
          <pose>0 0 0 0 -0 0</pose>
          <mass>0.0001</mass>
          <inertia>
            <ixx>0.0001</ixx>
            <ixy>0</ixy>
            <ixz>0</ixz>
            <iyy>0.0001</iyy>
            <iyz>0</iyz>
            <izz>0.0001</izz>
          </inertia>
        </inertial>
        <collision name='camera_link_collision'>
          <pose>0 0 0 0 -0 0</pose>
          <geometry>
          <box>
            <size>0.05 0.05 0.05</size>
          </box>
          </geometry>
          <surface>
            <contact>
              <ode/>
            </contact>
            <friction>
              <ode/>
            </friction>
            <bounce/>
          </surface>
          <max_contacts>10</max_contacts>
        </collision>
        <visual name='camera_link_visual'>
          <pose>0 0 0 0 -0 0</pose>
          <geometry>
            <mesh>
              <scale>1 1 1</scale>
              <uri>model://hku_m100/gimbal.dae</uri>
            </mesh>
          </geometry>
        </visual>
        <gravity>0</gravity>
        <velocity_decay>
          <linear>0</linear>
          <angular>0</angular>
        </velocity_decay>
        <self_collide>0</self_collide>
        <sensor name='camera_camera_sensor' type='camera'>
          <update_rate>10</update_rate>
          <camera name='__default__'>
            <pose>0.0 0 0 0 1.570796326794897 0</pose>
            <horizontal_fov>1.64061</horizontal_fov>
            <image>
              <format>R8G8B8</format>
              <width>640</width>
              <height>480</height>
            </image>
            <clip>
              <near>0.01</near>
              <far>100</far>
            </clip>
          </camera>
          <plugin name='camera_controller' filename='libgazebo_ros_camera.so'>
            <cameraName>camera</cameraName>
            <alwaysOn>true</alwaysOn>
            <updateRate>10</updateRate>
            <imageTopicName>/dji_sdk/image_raw</imageTopicName>
            <cameraInfoTopicName>/dji_sdk/camera_info</cameraInfoTopicName>
            <frameName>camera_optical_frame</frameName>
            <robotNamespace>/</robotNamespace>
          </plugin>
        </sensor>
        <kinematic>0</kinematic>
      </link>
      <link name='gimbal_link'>
        <pose>0 0 -0.04 0 -0 0</pose>
        <inertial>
          <pose>0 0 0 0 -0 0</pose>
          <mass>0.001</mass>
          <inertia>
            <ixx>0.0001</ixx>
            <ixy>0</ixy>
            <ixz>0</ixz>
            <iyy>0.0001</iyy>
            <iyz>0</iyz>
            <izz>0.0001</izz>
          </inertia>
        </inertial>
        <velocity_decay>
          <linear>0</linear>
          <angular>0</angular>
        </velocity_decay>
        <self_collide>0</self_collide>
        <kinematic>0</kinematic>
        <gravity>1</gravity>
      </link>
      <joint name='gimbal_joint' type='revolute'>
        <pose>0 0 0 0 -0 0</pose>
        <child>gimbal_link</child>
        <parent>base_link</parent>
        <axis>
          <xyz>1 0 0</xyz>
          <limit>
            <lower>0</lower>
            <upper>0</upper>
          </limit>
        </axis>
      </joint>
      <joint name='base_yaw_joint' type='revolute'>
        <pose>0 0 0 0 -0 0</pose>
        <child>yaw_link</child>
        <parent>gimbal_link</parent>
        <axis>
          <xyz>0 0 1</xyz>
          <limit>
            <lower>-1e+16</lower>
            <upper>1e+16</upper>
          </limit>
        </axis>
      </joint>
      <link name='roll_link'>
        <pose>0 0 -0.04 0 -0 0</pose>
        <inertial>
          <pose>0 0 0 0 -0 0</pose>
          <mass>0.001</mass>
          <inertia>
            <ixx>0.0001</ixx>
            <ixy>0</ixy>
            <ixz>0</ixz>
            <iyy>0.0001</iyy>
            <iyz>0</iyz>
            <izz>0.0001</izz>
          </inertia>
        </inertial>
        <velocity_decay>
          <linear>0</linear>
          <angular>0</angular>
        </velocity_decay>
        <self_collide>0</self_collide>
        <kinematic>0</kinematic>
        <gravity>0</gravity>
      </link>
      <link name='yaw_link'>
        <pose>0 0 -0.04 0 -0 0</pose>
        <inertial>
          <pose>0 0 0 0 -0 0</pose>
          <mass>0.001</mass>
          <inertia>
            <ixx>0.0001</ixx>
            <ixy>0</ixy>
            <ixz>0</ixz>
            <iyy>0.0001</iyy>
            <iyz>0</iyz>
            <izz>0.001</izz>
          </inertia>
        </inertial>
        <velocity_decay>
          <linear>0</linear>
          <angular>0</angular>
        </velocity_decay>
        <self_collide>0</self_collide>
        <kinematic>0</kinematic>
        <gravity>0</gravity>
      </link>
      <link name='pitch_link'>
        <pose>0 0 -0.04 0 -0 0</pose>
        <inertial>
          <pose>0 0 0 0 -0 0</pose>
          <mass>0.001</mass>
          <inertia>
            <ixx>0.0001</ixx>
            <ixy>0</ixy>
            <ixz>0</ixz>
            <iyy>0.0001</iyy>
            <iyz>0</iyz>
            <izz>0.0001</izz>
          </inertia>
        </inertial>
        <velocity_decay>
          <linear>0</linear>
          <angular>0</angular>
        </velocity_decay>
        <self_collide>0</self_collide>
        <kinematic>0</kinematic>
        <gravity>0</gravity>
      </link>
      <joint name='yaw_roll_joint' type='revolute'>
        <pose>0 0 0 0 -0 0</pose>
        <child>roll_link</child>
        <parent>yaw_link</parent>
        <axis>
          <xyz>1 0 0</xyz>
          <limit>
            <lower>-1e+16</lower>
            <upper>1e+16</upper>
          </limit>
        </axis>
      </joint>
      <joint name='roll_pitch_joint' type='revolute'>
        <pose>0 0 0 0 -0 0</pose>
        <child>pitch_link</child>
        <parent>roll_link</parent>
        <axis>
          <xyz>0 1 0</xyz>
          <limit>
            <lower>-1e+16</lower>
            <upper>1e+16</upper>
          </limit>
        </axis>
      </joint>
      <joint name='camera_joint' type='revolute'>
        <pose>0 0 0 0 -0 0</pose>
        <child>camera_link</child>
        <parent>pitch_link</parent>
        <axis>
          <xyz>0 1 0</xyz>
          <limit>
            <lower>0</lower>
            <upper>0</upper>
          </limit>
        </axis>
      </joint>
      <static>0</static>
    </model>
    <model name="box">
      <link name="box_link">
		<pose>0 0 0 0 0 0</pose>
		<inertial>
			<mass>1</mass>
		</inertial>
        <collision name="collision">
          <geometry>
            <box>
              <size>1 1 0.2</size>
            </box>
          </geometry>
          <surface>
              <bounce><restitution_coefficient>0</restitution_coefficient></bounce>
          </surface>
        </collision>

        <visual name="visual">
          <geometry>
            <box>
              <size>1 1 0.2</size>
            </box>
          </geometry>
          <material>
			<ambient>1 0 0 1</ambient>
			<diffuse>1 0 0 1</diffuse>
			<specular>0.1 0.1 0.1 1</specular>
			<emissive>0 0 0 0</emissive>
		 </material>
        </visual>
        </link>
        <link name="tag_link">
		  <pose>0 0 0.1 0 0 0</pose>
		  <inertial>
			<mass>0.0001</mass> 
		  </inertial>
		  <collision name="tag_collision">
		   <geometry>
            <box>
              <size>0.5 0.5 0.01</size>
            </box>
          </geometry>
          <surface>
              <bounce><restitution_coefficient>0</restitution_coefficient></bounce>
		  </surface>
		  </collision>
        <visual name="tag_visual">
          <geometry>
            <box>
              <size>0.5 0.5 0.01</size>
            </box>
          </geometry>
          <material>
            <script>
              <uri>model://tags/Media/materials/scripts/tags.material</uri>
              <uri>model://tags/Media/materials/textures</uri>
              <name>Tags/Tag36_11_00000</name>
            </script>
          </material>
        </visual>
        </link>
        <joint name="base_joint" type="fixed">  
        <parent>box_link</parent>
        <child>tag_link</child>
        </joint>
      <plugin name="model_push" filename="libmodel_push.so">
	  </plugin>
    </model>
  </world>
</sdf>
